Workbook

Sheet ข้อมูลออเดอร์
A1: ERP No. | B1: Box Qty | C1: Print Label | D1: Order Mark | E1: Courier | F1: Waybill No. | G1: Outbound Status | H1: Priority | I1: Route State | J1: Manual Status | K1: Order type | L1: Create Time | M1: Closed Time | N1: Interface Status | O1: Shop Name | P1: Warehouse Code | Q1: Owner Code | R1: Remarks | S1: Release status | T1: Virtual WH | U1: Virtual Owner | V1: Shop Group Name | W1: File | X1: Video | Y1: Error Status | Z1: Upstream Cancel | AA1: Cancel Time | AB1: ETA | AC1: Payment Time | AD1: Platform No. | AE1: WMS No. | AF1: Wave No. | AG1: Position No. | AH1: Order Source | AI1: Rel Order No. | AJ1: Rel Order Type | AK1: Intfc Fail Reason | AL1: Customer name | AM1: Recipient Country Code | AN1: Consignee Co. | AO1: Receipt Province | AP1: Receipt City | AQ1: Receipt Area | AR1: จังหวัด | AS1: เขต/อำเภอ | AT1: รหัสไปรษณีย์ | AU1: Receive Town | AV1: Consignee Addr | AW1: Receive Name | AX1: Receiver Mobile Number | AY1: Receiver Email | AZ1: Receiver Zipcode | BA1: Shipper Country Code | BB1: Shipper Co | BC1: Shipper Prov | BD1: Shipper City | BE1: Shipper Area | BF1: Shipper Town | BG1: Shipper Address | BH1: Shipper Name | BI1: Shipper Mobile | BJ1: Shipper Email | BK1: Shipper Zip | BL1: Create by | BM1: Pick Time | BN1: Picker | BO1: Check Time | BP1: Recheck by | BQ1: Ship Time | BR1: Shipper | BS1: Buyer Shortname | BT1: Buyer message | BU1: Seller Nick Name | BV1: Comment by seller | BW1: Goods-gather Code | BX1: Custom 1 | BY1: Custom 2 | BZ1: Custom 3 | CA1: Custom 4 | CB1: Expected Orders | CC1: SKU Qty | CD1: Exp. Net Wt. | CE1: Box Qty.1 | CF1: Ship Wt | CG1: Package Weight | CH1: Package Volume | CI1: Order Volume | CJ1: Shipping volume | CK1: Pallet Qty | CL1: Transit Time | CM1: Trace Info | CN1: Shipped Qty | CO1: Exp. Gross Wt. | CP1: Order Mark.1 | CQ1: Error | CR1: Receivable Amount | CS1: Op Status | CT1: Line No. | CU1: Product name | CV1: Product Code | CW1: Product Barcode | CX1: UOM | CY1: UOM.1 | CZ1: Unit Qty | DA1: Expect Qty | DB1: Available Split Qty | DC1: Unalloc Qty | DD1: Allocated Qty | DE1: Pick Qty | DF1: Check Qty | DG1: Shipped Qty.1 | DH1: Adjusted | DI1: Location | DJ1: LPN No. | DK1: Item No. | DL1: Price | DM1: size | DN1: Color | DO1: Style | DP1: Specification | DQ1: From No. | DR1: Line UDF 1 | DS1: Line UDF 2 | DT1: Line UDF 3 | DU1: Line UDF 4 | DV1: Line UDF 5 | DW1: Line UDF 6 | DX1: Line UDF 7 | DY1: Line UDF 8 | DZ1: Inbound Date | EA1: Production Date | EB1: Expiry Date | EC1: Quality Status | ED1: Batch No. | EE1: Virtual WH.1 | EF1: BOM版本 | EG1: Shelf life | EH1: Halal | EI1: Product Barcode 1 | EJ1: Product Barcode 2 | EK1: Product Barcode 3 | EL1: Product Barcode 4 | EM1: Product Barcode 5 | EN1: express_company_name
A2: KOO26092200116 | C2: 00000000000000000000 | E2: OTHER | G2: stockout_allocated | H2: 3 | J2: order_allocate | K2: KOL订单 | L2: 2026-09-22 08:01:14 | N2: 00000000000000000000 | O2: KOL | P2: TH01 | Q2: B2C | S2: unnecessary | T2: TH01 | W2: N | X2: N | Y2: intercept_action_nostart | Z2: uncancelled | AE2: CK01967003024260922000663 | AH2: OTHER | AO2: จังหวัดกรุงเทพมหานคร | AP2: เขตห้วยขวาง | AQ2: ห้วยขวาง | AR2: กรุงเทพมหานคร/ Bangkok | AS2: ห้วยขวาง/ Huai Khwang | AT2: 10310 | AV2: คอนโด ไลฟ์ รัชดาภิเษก ห้อง806 เลขที่ 279 ถ. รัชดาภิเษก แขวงห้วยขวาง เขตห้วยขวาง กรุงเทพมหานคร 10310 0909157151 | AW2: Foofoam | AX2: 0909157151 | AZ2: 10310 | BL2: openapi | BV2: Express delivery | CB2: 2 | CC2: 2 | CS2: ACCEPT | CT2: 000001 | CU2: ULTRA COVER WEIGHTLESS COLOR CORRECTOR PINK BLOSSOM | CV2: SKINTIFIC-492003 | CW2: 4897147696014 | CX2: 件 | CY2: 件 | CZ2: 1 | DA2: 1 | DD2: 1 | EC2: ZP | EE2: TH01 | EN2: OTHER
A3: KOO26092200116 | C3: 00000000000000000000 | E3: OTHER | G3: stockout_allocated | H3: 3 | J3: order_allocate | K3: KOL订单 | L3: 2026-09-22 08:01:14 | N3: 00000000000000000000 | O3: KOL | P3: TH01 | Q3: B2C | S3: unnecessary | T3: TH01 | W3: N | X3: N | Y3: intercept_action_nostart | Z3: uncancelled | AE3: CK01967003024260922000663 | AH3: OTHER | AO3: จังหวัดกรุงเทพมหานคร | AP3: เขตห้วยขวาง | AQ3: ห้วยขวาง | AR3: กรุงเทพมหานคร/ Bangkok | AS3: ห้วยขวาง/ Huai Khwang | AT3: 10310 | AV3: คอนโด ไลฟ์ รัชดาภิเษก ห้อง806 เลขที่ 279 ถ. รัชดาภิเษก แขวงห้วยขวาง เขตห้วยขวาง กรุงเทพมหานคร 10310 0909157151 | AW3: Foofoam | AX3: 0909157151 | AZ3: 10310 | BL3: openapi | BV3: Express delivery | CB3: 2 | CC3: 2 | CS3: ACCEPT | CT3: 000002 | CU3: ULTRA COVER WEIGHTLESS COLOR CORRECTOR SKY BLUE | CV3: SKINTIFIC-492001 | CW3: 4897147695994 | CX3: 件 | CY3: 件 | CZ3: 1 | DA3: 1 | DD3: 1 | EC3: ZP | EE3: TH01 | EN3: OTHER
A4: KOO26092200117 | C4: 00000000000000000000 | E4: OTHER | G4: stockout_allocated | H4: 3 | J4: order_allocate | K4: KOL订单 | L4: 2026-09-22 08:01:15 | N4: 00000000000000000000 | O4: KOL | P4: TH01 | Q4: B2C | S4: unnecessary | T4: TH01 | W4: N | X4: N | Y4: intercept_action_nostart | Z4: uncancelled | AE4: CK01967003024260922000664 | AH4: OTHER | AO4: ตราด | AP4: บ่อไร่ | AQ4: บ่อพลอย | AR4: ตราด/ Trat | AS4: บ่อไร่/ Bo Rai | AT4: 23140 | AV4: 252/4 ม. 3 | AW4: สุภาภรณ์ สุภาพงษ์ | AX4: 0654964564 | AZ4: 23140 | BL4: openapi | BV4: Express delivery | CB4: 2 | CC4: 2 | CS4: ACCEPT | CT4: 000001 | CU4: ULTRA COVER WEIGHTLESS COLOR CORRECTOR PINK BLOSSOM | CV4: SKINTIFIC-492003 | CW4: 4897147696014 | CX4: 件 | CY4: 件 | CZ4: 1 | DA4: 1 | DD4: 1 | EC4: ZP | EE4: TH01 | EN4: OTHER
A5: KOO26092200117 | C5: 00000000000000000000 | E5: OTHER | G5: stockout_allocated | H5: 3 | J5: order_allocate | K5: KOL订单 | L5: 2026-09-22 08:01:15 | N5: 00000000000000000000 | O5: KOL | P5: TH01 | Q5: B2C | S5: unnecessary | T5: TH01 | W5: N | X5: N | Y5: intercept_action_nostart | Z5: uncancelled | AE5: CK01967003024260922000664 | AH5: OTHER | AO5: ตราด | AP5: บ่อไร่ | AQ5: บ่อพลอย | AR5: ตราด/ Trat | AS5: บ่อไร่/ Bo Rai | AT5: 23140 | AV5: 252/4 ม. 3 | AW5: สุภาภรณ์ สุภาพงษ์ | AX5: 0654964564 | AZ5: 23140 | BL5: openapi | BV5: Express delivery | CB5: 2 | CC5: 2 | CS5: ACCEPT | CT5: 000002 | CU5: ULTRA COVER WEIGHTLESS COLOR CORRECTOR SKY BLUE | CV5: SKINTIFIC-492001 | CW5: 4897147695994 | CX5: 件 | CY5: 件 | CZ5: 1 | DA5: 1 | DD5: 1 | EC5: ZP | EE5: TH01 | EN5: OTHER
A6: KOO26092200118 | C6: 00000000000000000000 | E6: OTHER | G6: stockout_allocated | H6: 3 | J6: order_allocate | K6: KOL订单 | L6: 2026-09-22 08:01:16 | N6: 00000000000000000000 | O6: KOL | P6: TH01 | Q6: B2C | S6: unnecessary | T6: TH01 | W6: N | X6: N | Y6: intercept_action_nostart | Z6: uncancelled | AE6: CK01967003024260922000665 | AH6: OTHER | AO6: ชลบุรี | AP6: อ.บางละมุง | AQ6: ต.นาเกลือ | AR6: ชลบุรี/ Chonburi | AS6: บางละมุง/ Bang Lamung | AT6: 20150 | AV6: Condo Natureza ตึกD ห้อง415/188 ม.4 ต.นาเกลือ อ.บางละมุง จ.ชลบุรี 20150 | AW6: กานต์กวิน | AX6: 0929649639 | AZ6: 20150 | BL6: openapi | BV6: Express delivery | CB6: 2 | CC6: 2 | CS6: ACCEPT | CT6: 000001 | CU6: ULTRA COVER WEIGHTLESS COLOR CORRECTOR PINK BLOSSOM | CV6: SKINTIFIC-492003 | CW6: 4897147696014 | CX6: 件 | CY6: 件 | CZ6: 1 | DA6: 1 | DD6: 1 | EC6: ZP | EE6: TH01 | EN6: OTHER
A7: KOO26092200118 | C7: 00000000000000000000 | E7: OTHER | G7: stockout_allocated | H7: 3 | J7: order_allocate | K7: KOL订单 | L7: 2026-09-22 08:01:16 | N7: 00000000000000000000 | O7: KOL | P7: TH01 | Q7: B2C | S7: unnecessary | T7: TH01 | W7: N | X7: N | Y7: intercept_action_nostart | Z7: uncancelled | AE7: CK01967003024260922000665 | AH7: OTHER | AO7: ชลบุรี | AP7: อ.บางละมุง | AQ7: ต.นาเกลือ | AR7: ชลบุรี/ Chonburi | AS7: บางละมุง/ Bang Lamung | AT7: 20150 | AV7: Condo Natureza ตึกD ห้อง415/188 ม.4 ต.นาเกลือ อ.บางละมุง จ.ชลบุรี 20150 | AW7: กานต์กวิน | AX7: 0929649639 | AZ7: 20150 | BL7: openapi | BV7: Express delivery | CB7: 2 | CC7: 2 | CS7: ACCEPT | CT7: 000002 | CU7: ULTRA COVER WEIGHTLESS COLOR CORRECTOR SKY BLUE | CV7: SKINTIFIC-492001 | CW7: 4897147695994 | CX7: 件 | CY7: 件 | CZ7: 1 | DA7: 1 | DD7: 1 | EC7: ZP | EE7: TH01 | EN7: OTHER
A8: KOO26092200119 | C8: 00000000000000000000 | E8: OTHER | G8: stockout_allocated | H8: 3 | J8: order_allocate | K8: KOL订单 | L8: 2026-09-22 08:01:17 | N8: 00000000000000000000 | O8: KOL | P8: TH01 | Q8: B2C | S8: unnecessary | T8: TH01 | W8: N | X8: N | Y8: intercept_action_nostart | Z8: uncancelled | AE8: CK01967003024260922000666 | AH8: OTHER | AO8: จังหวัดกรุงเทพมหานคร | AP8: เขตคลองเตย | AQ8: คลองเตย | AR8: กรุงเทพมหานคร/ Bangkok | AS8: คลองเตย/ Khlong Toei | AT8: 10110 | AV8: เลขที่ 88 อาคารเดอะ ปาร์ค ห้องเลขที่ 5E02-5E09 ชั้นที่ 5 ฝั่ง East Wing ถนนรัชดาภิเษก แขวงคลองเตย เขตคลองเตย กรุงเทพมหานคร | AW8: Baball CP SKT TT | AX8: 0892234015 | AZ8: 10110 | BL8: openapi | BV8: Lalamove | CB8: 25 | CC8: 2 | CS8: ACCEPT | CT8: 000001 | CU8: ULTRA COVER WEIGHTLESS COLOR CORRECTOR SKY BLUE | CV8: SKINTIFIC-492001 | CW8: 4897147695994 | CX8: 件 | CY8: 件 | CZ8: 12 | DA8: 12 | DD8: 12 | EC8: ZP | EE8: TH01 | EN8: OTHER
A9: KOO26092200119 | C9: 00000000000000000000 | E9: OTHER | G9: stockout_allocated | H9: 3 | J9: order_allocate | K9: KOL订单 | L9: 2026-09-22 08:01:17 | N9: 00000000000000000000 | O9: KOL | P9: TH01 | Q9: B2C | S9: unnecessary | T9: TH01 | W9: N | X9: N | Y9: intercept_action_nostart | Z9: uncancelled | AE9: CK01967003024260922000666 | AH9: OTHER | AO9: จังหวัดกรุงเทพมหานคร | AP9: เขตคลองเตย | AQ9: คลองเตย | AR9: กรุงเทพมหานคร/ Bangkok | AS9: คลองเตย/ Khlong Toei | AT9: 10110 | AV9: เลขที่ 88 อาคารเดอะ ปาร์ค ห้องเลขที่ 5E02-5E09 ชั้นที่ 5 ฝั่ง East Wing ถนนรัชดาภิเษก แขวงคลองเตย เขตคลองเตย กรุงเทพมหานคร | AW9: Baball CP SKT TT | AX9: 0892234015 | AZ9: 10110 | BL9: openapi | BV9: Lalamove | CB9: 25 | CC9: 2 | CS9: ACCEPT | CT9: 000002 | CU9: ULTRA COVER WEIGHTLESS COLOR CORRECTOR PINK BLOSSOM | CV9: SKINTIFIC-492003 | CW9: 4897147696014 | CX9: 件 | CY9: 件 | CZ9: 13 | DA9: 13 | DD9: 13 | EC9: ZP | EE9: TH01 | EN9: OTHER
A10: KOO26092200120 | C10: 00000000000000000000 | E10: OTHER | G10: stockout_allocated | H10: 3 | J10: order_allocate | K10: KOL订单 | L10: 2026-09-22 08:01:17 | N10: 00000000000000000000 | O10: KOL | P10: TH01 | Q10: B2C | S10: unnecessary | T10: TH01 | W10: N | X10: N | Y10: intercept_action_nostart | Z10: uncancelled | AE10: CK01967003024260922000667 | AH10: OTHER | AO10: จังหวัดกรุงเทพมหานคร | AP10: เขตคันนายาว | AQ10: คันนายาว | AR10: กรุงเทพมหานคร/ Bangkok | AS10: คันนายาว/ Khan Na Yao | AT10: 10230 | AV10: 98/26 Blossom Condo Fashion ตึก Altitude ถ.รัชดา-รามอินทรา | AW10: ธนพร ภัครังสิสกุล | AX10: 0918851584 | AZ10: 10230 | BL10: openapi | BV10: Express delivery | CB10: 2 | CC10: 2 | CS10: ACCEPT | CT10: 000001 | CU10: ULTRA COVER WEIGHTLESS COLOR CORRECTOR SKY BLUE | CV10: SKINTIFIC-492001 | CW10: 4897147695994 | CX10: 件 | CY10: 件 | CZ10: 1 | DA10: 1 | DD10: 1 | EC10: ZP | EE10: TH01 | EN10: OTHER
A11: KOO26092200120 | C11: 00000000000000000000 | E11: OTHER | G11: stockout_allocated | H11: 3 | J11: order_allocate | K11: KOL订单 | L11: 2026-09-22 08:01:17 | N11: 00000000000000000000 | O11: KOL | P11: TH01 | Q11: B2C | S11: unnecessary | T11: TH01 | W11: N | X11: N | Y11: intercept_action_nostart | Z11: uncancelled | AE11: CK01967003024260922000667 | AH11: OTHER | AO11: จังหวัดกรุงเทพมหานคร | AP11: เขตคันนายาว | AQ11: คันนายาว | AR11: กรุงเทพมหานคร/ Bangkok | AS11: คันนายาว/ Khan Na Yao | AT11: 10230 | AV11: 98/26 Blossom Condo Fashion ตึก Altitude ถ.รัชดา-รามอินทรา | AW11: ธนพร ภัครังสิสกุล | AX11: 0918851584 | AZ11: 10230 | BL11: openapi | BV11: Express delivery | CB11: 2 | CC11: 2 | CS11: ACCEPT | CT11: 000002 | CU11: ULTRA COVER WEIGHTLESS COLOR CORRECTOR PINK BLOSSOM | CV11: SKINTIFIC-492003 | CW11: 4897147696014 | CX11: 件 | CY11: 件 | CZ11: 1 | DA11: 1 | DD11: 1 | EC11: ZP | EE11: TH01 | EN11: OTHER
A12: KOO26092200121 | C12: 00000000000000000000 | E12: OTHER | G12: stockout_allocated | H12: 3 | J12: order_allocate | K12: KOL订单 | L12: 2026-09-22 08:01:18 | N12: 00000000000000000000 | O12: KOL | P12: TH01 | Q12: B2C | S12: unnecessary | T12: TH01 | W12: N | X12: N | Y12: intercept_action_nostart | Z12: uncancelled | AE12: CK01967003024260922000668 | AH12: OTHER | AO12: จังหวัดกรุงเทพมหานคร | AP12: เขตจตุจักร | AQ12: ลาดยาว | AR12: กรุงเทพมหานคร/ Bangkok | AS12: จตุจักร/ Chatuchak | AT12: 10900 | AV12: Fluke Kunyada 252/125 Vantage condominium ratchada road Ladyao Chatuchak BKK 10900 Thailand | AW12: Fluke Kunyada | AX12: 0870122635 | AZ12: 10900 | BL12: openapi | BV12: Express delivery | CB12: 2 | CC12: 1 | CO12: 2 | CS12: ACCEPT | CT12: 000001 | CU12: PDRN面霜 | CV12: SKINTIFIC-351 | CW12: 4897147691323 | CX12: 件 | CY12: 件 | CZ12: 2 | DA12: 2 | DD12: 2 | EC12: ZP | EE12: TH01 | EN12: OTHER
A13: KOO26092200122 | C13: 00000000000000000000 | E13: OTHER | G13: stockout_allocated | H13: 3 | J13: order_allocate | K13: KOL订单 | L13: 2026-09-22 08:01:19 | N13: 00000000000000000000 | O13: KOL | P13: TH01 | Q13: B2C | R13: ณัฏฐธิดา รื่นนุสานห้อง509 เลขที่บ้าน Sanaar Living 31 ซอยพหลโยธิน 87 ซอย 6 ตำบลประชาธิปัตย์ อำเภอธัญบุรี จังหวัดปทุมธานี 12130โทร0988287633ค่ะ | S13: unnecessary | T13: TH01 | W13: N | X13: N | Y13: intercept_action_nostart | Z13: uncancelled | AE13: CK01967003024260922000669 | AH13: OTHER | AO13: จังหวัดปทุมธานี | AP13: อำเภอธัญบุรี | AQ13: ประชาธิปัตย์ | AR13: ปทุมธานี/ Pathum Thani | AS13: ธัญบุรี/ Thanyaburi | AT13: 12130 | AV13: ณัฏฐธิดา รื่นนุสานห้อง509 เลขที่บ้าน Sanaar Living 31 ซอยพหลโยธิน 87 ซอย 6 ตำบลประชาธิปัตย์ อำเภอธัญบุรี จังหวัดปทุมธานี 12130 โทร0988287633ค่ะ | AW13: ณัฏฐธิดา รื่นนุสาน | AX13: 0988287633 | AZ13: 12130 | BL13: openapi | BV13: Express delivery | CB13: 1 | CC13: 1 | CO13: 167 | CS13: ACCEPT | CT13: 000001 | CU13: Radiance Booster Serum Spray | CV13: SKINTIFIC-170 | CW13: 810114872833 | CX13: 件 | CY13: 件 | CZ13: 1 | DA13: 1 | DD13: 1 | EC13: ZP | EE13: TH01 | EI13: S-170 | EN13: OTHER
A14: KOO26092200123 | C14: 00000000000000000000 | E14: OTHER | G14: stockout_allocated | H14: 3 | J14: order_allocate | K14: KOL订单 | L14: 2026-09-22 08:01:19 | N14: 00000000000000000000 | O14: KOL | P14: TH01 | Q14: B2C | S14: unnecessary | T14: TH01 | W14: N | X14: N | Y14: intercept_action_nostart | Z14: uncancelled | AE14: CK01967003024260922000670 | AH14: OTHER | AO14: จังหวัดนนทบุรี | AP14: อำเภอบางใหญ่ | AQ14: บางม่วง | AR14: นนทบุรี/ Nonthaburi | AS14: บางใหญ่/ Bang Yai | AT14: 11140 | AV14: 56/14 ม.14 มบ.เนเจอร์โฮม ซอยวัดสังวร ต.บางม่วง อ.บางใหญ่ จ.นนทบุรี 11140 | AW14: น.ส.ภาณิชญา ทันตาหะ | AX14: 0648141444 | AZ14: 11140 | BL14: openapi | BV14: Express delivery | CB14: 1 | CC14: 1 | CO14: 1.2 | CS14: ACCEPT | CT14: 000001 | CU14: Niacinamide Brightening Daily Mask | CV14: SKINTIFIC-31001 | CW14: 4897147691262 | CX14: 件 | CY14: 件 | CZ14: 1 | DA14: 1 | DD14: 1 | EC14: ZP | EE14: TH01 | EN14: OTHER
A15: KOO26092200124 | C15: 00000000000000000000 | E15: OTHER | G15: stockout_allocated | H15: 3 | J15: order_allocate | K15: KOL订单 | L15: 2026-09-22 08:01:20 | N15: 00000000000000000000 | O15: KOL | P15: TH01 | Q15: B2C | S15: unnecessary | T15: TH01 | W15: N | X15: N | Y15: intercept_action_nostart | Z15: uncancelled | AE15: CK01967003024260922000671 | AH15: OTHER | AO15: จังหวัดยะลา | AP15: อำเภอกรงปินัง | AQ15: กรงปินัง | AR15: ยะลา/ Yala | AS15: กรงปินัง/ Krong Pinang | AT15: 95000 | AV15: 23 หมู่5 | AW15: อัสมะห์ ยือล๊ะ | AX15: 0937437050 | AZ15: 95000 | BL15: openapi | BV15: Express delivery | CB15: 21 | CC15: 21 | CO15: 805.43 | CS15: ACCEPT | CT15: 000001 | CU15: SKINTIFIC PERFECT STAY VELVET MATTE CUSHION 02W Warm Ivory | CV15: SKINTIFIC-1342W | CW15: 810114872284 | CX15: 件 | CY15: 件 | CZ15: 1 | DA15: 1 | DD15: 1 | EC15: ZP | EE15: TH01 | EI15: S-1342W | EN15: OTHER
A16: KOO26092200124 | C16: 00000000000000000000 | E16: OTHER | G16: stockout_allocated | H16: 3 | J16: order_allocate | K16: KOL订单 | L16: 2026-09-22 08:01:20 | N16: 00000000000000000000 | O16: KOL | P16: TH01 | Q16: B2C | S16: unnecessary | T16: TH01 | W16: N | X16: N | Y16: intercept_action_nostart | Z16: uncancelled | AE16: CK01967003024260922000671 | AH16: OTHER | AO16: จังหวัดยะลา | AP16: อำเภอกรงปินัง | AQ16: กรงปินัง | AR16: ยะลา/ Yala | AS16: กรงปินัง/ Krong Pinang | AT16: 95000 | AV16: 23 หมู่5 | AW16: อัสมะห์ ยือล๊ะ | AX16: 0937437050 | AZ16: 95000 | BL16: openapi | BV16: Express delivery | CB16: 21 | CC16: 21 | CO16: 805.43 | CS16: ACCEPT | CT16: 000002 | CU16: SKINTIFIC PERFECT STAY VELVET MATTE CUSHION 00N Natural Porcelain | CV16: SKINTIFIC-1340N | CW16: 810114872239 | CX16: 件 | CY16: 件 | CZ16: 1 | DA16: 1 | DD16: 1 | EC16: ZP | EE16: TH01 | EI16: S-1340N | EN16: OTHER
A17: KOO26092200124 | C17: 00000000000000000000 | E17: OTHER | G17: stockout_allocated | H17: 3 | J17: order_allocate | K17: KOL订单 | L17: 2026-09-22 08:01:20 | N17: 00000000000000000000 | O17: KOL | P17: TH01 | Q17: B2C | S17: unnecessary | T17: TH01 | W17: N | X17: N | Y17: intercept_action_nostart | Z17: uncancelled | AE17: CK01967003024260922000671 | AH17: OTHER | AO17: จังหวัดยะลา | AP17: อำเภอกรงปินัง | AQ17: กรงปินัง | AR17: ยะลา/ Yala | AS17: กรงปินัง/ Krong Pinang | AT17: 95000 | AV17: 23 หมู่5 | AW17: อัสมะห์ ยือล๊ะ | AX17: 0937437050 | AZ17: 95000 | BL17: openapi | BV17: Express delivery | CB17: 21 | CC17: 21 | CO17: 805.43 | CS17: ACCEPT | CT17: 000003 | CU17: BRIGHTENING LIP SERUM Ruby Pop | CV17: SKINTIFIC-12312 | CW17: 4897147693310 | CX17: 件 | CY17: 件 | CZ17: 1 | DA17: 1 | DD17: 1 | EC17: ZP | EE17: TH01 | EI17: S-12312 | EN17: OTHER
A18: KOO26092200124 | C18: 00000000000000000000 | E18: OTHER | G18: stockout_allocated | H18: 3 | J18: order_allocate | K18: KOL订单 | L18: 2026-09-22 08:01:20 | N18: 00000000000000000000 | O18: KOL | P18: TH01 | Q18: B2C | S18: unnecessary | T18: TH01 | W18: N | X18: N | Y18: intercept_action_nostart | Z18: uncancelled | AE18: CK01967003024260922000671 | AH18: OTHER | AO18: จังหวัดยะลา | AP18: อำเภอกรงปินัง | AQ18: กรงปินัง | AR18: ยะลา/ Yala | AS18: กรงปินัง/ Krong Pinang | AT18: 95000 | AV18: 23 หมู่5 | AW18: อัสมะห์ ยือล๊ะ | AX18: 0937437050 | AZ18: 95000 | BL18: openapi | BV18: Express delivery | CB18: 21 | CC18: 21 | CO18: 805.43 | CS18: ACCEPT | CT18: 000004 | CU18: Radiance Booster Serum Spray | CV18: SKINTIFIC-170 | CW18: 810114872833 | CX18: 件 | CY18: 件 | CZ18: 1 | DA18: 1 | DD18: 1 | EC18: ZP | EE18: TH01 | EI18: S-170 | EN18: OTHER
A19: KOO26092200124 | C19: 00000000000000000000 | E19: OTHER | G19: stockout_allocated | H19: 3 | J19: order_allocate | K19: KOL订单 | L19: 2026-09-22 08:01:20 | N19: 00000000000000000000 | O19: KOL | P19: TH01 | Q19: B2C | S19: unnecessary | T19: TH01 | W19: N | X19: N | Y19: intercept_action_nostart | Z19: uncancelled | AE19: CK01967003024260922000671 | AH19: OTHER | AO19: จังหวัดยะลา | AP19: อำเภอกรงปินัง | AQ19: กรงปินัง | AR19: ยะลา/ Yala | AS19: กรงปินัง/ Krong Pinang | AT19: 95000 | AV19: 23 หมู่5 | AW19: อัสมะห์ ยือล๊ะ | AX19: 0937437050 | AZ19: 95000 | BL19: openapi | BV19: Express delivery | CB19: 21 | CC19: 21 | CO19: 805.43 | CS19: ACCEPT | CT19: 000005 | CU19: Cover Glow Perfect Cushion 02W Warm Ivory | CV19: SKINTIFIC-3262W | CW19: 4897147691293 | CX19: 件 | CY19: 件 | CZ19: 1 | DA19: 1 | DD19: 1 | EC19: ZP | EE19: TH01 | EN19: OTHER
A20: KOO26092200124 | C20: 00000000000000000000 | E20: OTHER | G20: stockout_allocated | H20: 3 | J20: order_allocate | K20: KOL订单 | L20: 2026-09-22 08:01:20 | N20: 00000000000000000000 | O20: KOL | P20: TH01 | Q20: B2C | S20: unnecessary | T20: TH01 | W20: N | X20: N | Y20: intercept_action_nostart | Z20: uncancelled | AE20: CK01967003024260922000671 | AH20: OTHER | AO20: จังหวัดยะลา | AP20: อำเภอกรงปินัง | AQ20: กรงปินัง | AR20: ยะลา/ Yala | AS20: กรงปินัง/ Krong Pinang | AT20: 95000 | AV20: 23 หมู่5 | AW20: อัสมะห์ ยือล๊ะ | AX20: 0937437050 | AZ20: 95000 | BL20: openapi | BV20: Express delivery | CB20: 21 | CC20: 21 | CO20: 805.43 | CS20: ACCEPT | CT20: 000006 | CU20: Cover Glow Perfect Cushion 01W Warm Vanilla | CV20: SKINTIFIC-3261W | CW20: 4897147691286 | CX20: 件 | CY20: 件 | CZ20: 1 | DA20: 1 | DD20: 1 | EC20: ZP | EE20: TH01 | EN20: OTHER
A21: KOO26092200124 | C21: 00000000000000000000 | E21: OTHER | G21: stockout_allocated | H21: 3 | J21: order_allocate | K21: KOL订单 | L21: 2026-09-22 08:01:20 | N21: 00000000000000000000 | O21: KOL | P21: TH01 | Q21: B2C | S21: unnecessary | T21: TH01 | W21: N | X21: N | Y21: intercept_action_nostart | Z21: uncancelled | AE21: CK01967003024260922000671 | AH21: OTHER | AO21: จังหวัดยะลา | AP21: อำเภอกรงปินัง | AQ21: กรงปินัง | AR21: ยะลา/ Yala | AS21: กรงปินัง/ Krong Pinang | AT21: 95000 | AV21: 23 หมู่5 | AW21: อัสมะห์ ยือล๊ะ | AX21: 0937437050 | AZ21: 95000 | BL21: openapi | BV21: Express delivery | CB21: 21 | CC21: 21 | CO21: 805.43 | CS21: ACCEPT | CT21: 000007 | CU21: 粉底棒 01N Natural Vanilla | CV21: SKINTIFIC-32101N | CW21: 4897147694041 | CX21: 件 | CY21: 件 | CZ21: 1 | DA21: 1 | DD21: 1 | EC21: ZP | EE21: TH01 | EN21: OTHER
A22: KOO26092200124 | C22: 00000000000000000000 | E22: OTHER | G22: stockout_allocated | H22: 3 | J22: order_allocate | K22: KOL订单 | L22: 2026-09-22 08:01:20 | N22: 00000000000000000000 | O22: KOL | P22: TH01 | Q22: B2C | S22: unnecessary | T22: TH01 | W22: N | X22: N | Y22: intercept_action_nostart | Z22: uncancelled | AE22: CK01967003024260922000671 | AH22: OTHER | AO22: จังหวัดยะลา | AP22: อำเภอกรงปินัง | AQ22: กรงปินัง | AR22: ยะลา/ Yala | AS22: กรงปินัง/ Krong Pinang | AT22: 95000 | AV22: 23 หมู่5 | AW22: อัสมะห์ ยือล๊ะ | AX22: 0937437050 | AZ22: 95000 | BL22: openapi | BV22: Express delivery | CB22: 21 | CC22: 21 | CO22: 805.43 | CS22: ACCEPT | CT22: 000008 | CU22: 粉底棒 03N Natural Petal | CV22: SKINTIFIC-32103N | CW22: 4897147694065 | CX22: 件 | CY22: 件 | CZ22: 1 | DA22: 1 | DD22: 1 | EC22: ZP | EE22: TH01 | EN22: OTHER
A23: KOO26092200124 | C23: 00000000000000000000 | E23: OTHER | G23: stockout_allocated | H23: 3 | J23: order_allocate | K23: KOL订单 | L23: 2026-09-22 08:01:20 | N23: 00000000000000000000 | O23: KOL | P23: TH01 | Q23: B2C | S23: unnecessary | T23: TH01 | W23: N | X23: N | Y23: intercept_action_nostart | Z23: uncancelled | AE23: CK01967003024260922000671 | AH23: OTHER | AO23: จังหวัดยะลา | AP23: อำเภอกรงปินัง | AQ23: กรงปินัง | AR23: ยะลา/ Yala | AS23: กรงปินัง/ Krong Pinang | AT23: 95000 | AV23: 23 หมู่5 | AW23: อัสมะห์ ยือล๊ะ | AX23: 0937437050 | AZ23: 95000 | BL23: openapi | BV23: Express delivery | CB23: 21 | CC23: 21 | CO23: 805.43 | CS23: ACCEPT | CT23: 000009 | CU23: 粉底棒 02N Natural Ivory | CV23: SKINTIFIC-32102N | CW23: 4897147694058 | CX23: 件 | CY23: 件 | CZ23: 1 | DA23: 1 | DD23: 1 | EC23: ZP | EE23: TH01 | EN23: OTHER
A24: KOO26092200124 | C24: 00000000000000000000 | E24: OTHER | G24: stockout_allocated | H24: 3 | J24: order_allocate | K24: KOL订单 | L24: 2026-09-22 08:01:20 | N24: 00000000000000000000 | O24: KOL | P24: TH01 | Q24: B2C | S24: unnecessary | T24: TH01 | W24: N | X24: N | Y24: intercept_action_nostart | Z24: uncancelled | AE24: CK01967003024260922000671 | AH24: OTHER | AO24: จังหวัดยะลา | AP24: อำเภอกรงปินัง | AQ24: กรงปินัง | AR24: ยะลา/ Yala | AS24: กรงปินัง/ Krong Pinang | AT24: 95000 | AV24: 23 หมู่5 | AW24: อัสมะห์ ยือล๊ะ | AX24: 0937437050 | AZ24: 95000 | BL24: openapi | BV24: Express delivery | CB24: 21 | CC24: 21 | CO24: 805.43 | CS24: ACCEPT | CT24: 000010 | CU24: Niacinamide Brightening Daily Mask | CV24: SKINTIFIC-31001 | CW24: 4897147691262 | CX24: 件 | CY24: 件 | CZ24: 1 | DA24: 1 | DD24: 1 | EC24: ZP | EE24: TH01 | EN24: OTHER
A25: KOO26092200124 | C25: 00000000000000000000 | E25: OTHER | G25: stockout_allocated | H25: 3 | J25: order_allocate | K25: KOL订单 | L25: 2026-09-22 08:01:20 | N25: 00000000000000000000 | O25: KOL | P25: TH01 | Q25: B2C | S25: unnecessary | T25: TH01 | W25: N | X25: N | Y25: intercept_action_nostart | Z25: uncancelled | AE25: CK01967003024260922000671 | AH25: OTHER | AO25: จังหวัดยะลา | AP25: อำเภอกรงปินัง | AQ25: กรงปินัง | AR25: ยะลา/ Yala | AS25: กรงปินัง/ Krong Pinang | AT25: 95000 | AV25: 23 หมู่5 | AW25: อัสมะห์ ยือล๊ะ | AX25: 0937437050 | AZ25: 95000 | BL25: openapi | BV25: Express delivery | CB25: 21 | CC25: 21 | CO25: 805.43 | CS25: ACCEPT | CT25: 000011 | CU25: 有色唇部精华10U | CV25: SKINTIFIC-12310U | CW25: 4897147693204 | CX25: 件 | CY25: 件 | CZ25: 1 | DA25: 1 | DD25: 1 | EC25: ZP | EE25: TH01 | EN25: OTHER
A26: KOO26092200124 | C26: 00000000000000000000 | E26: OTHER | G26: stockout_allocated | H26: 3 | J26: order_allocate | K26: KOL订单 | L26: 2026-09-22 08:01:20 | N26: 00000000000000000000 | O26: KOL | P26: TH01 | Q26: B2C | S26: unnecessary | T26: TH01 | W26: N | X26: N | Y26: intercept_action_nostart | Z26: uncancelled | AE26: CK01967003024260922000671 | AH26: OTHER | AO26: จังหวัดยะลา | AP26: อำเภอกรงปินัง | AQ26: กรงปินัง | AR26: ยะลา/ Yala | AS26: กรงปินัง/ Krong Pinang | AT26: 95000 | AV26: 23 หมู่5 | AW26: อัสมะห์ ยือล๊ะ | AX26: 0937437050 | AZ26: 95000 | BL26: openapi | BV26: Express delivery | CB26: 21 | CC26: 21 | CO26: 805.43 | CS26: ACCEPT | CT26: 000012 | CU26: 有色唇部精华07U | CV26: SKINTIFIC-1237U | CW26: 4897147693174 | CX26: 件 | CY26: 件 | CZ26: 1 | DA26: 1 | DD26: 1 | EC26: ZP | EE26: TH01 | EN26: OTHER
A27: KOO26092200124 | C27: 00000000000000000000 | E27: OTHER | G27: stockout_allocated | H27: 3 | J27: order_allocate | K27: KOL订单 | L27: 2026-09-22 08:01:20 | N27: 00000000000000000000 | O27: KOL | P27: TH01 | Q27: B2C | S27: unnecessary | T27: TH01 | W27: N | X27: N | Y27: intercept_action_nostart | Z27: uncancelled | AE27: CK01967003024260922000671 | AH27: OTHER | AO27: จังหวัดยะลา | AP27: อำเภอกรงปินัง | AQ27: กรงปินัง | AR27: ยะลา/ Yala | AS27: กรงปินัง/ Krong Pinang | AT27: 95000 | AV27: 23 หมู่5 | AW27: อัสมะห์ ยือล๊ะ | AX27: 0937437050 | AZ27: 95000 | BL27: openapi | BV27: Express delivery | CB27: 21 | CC27: 21 | CO27: 805.43 | CS27: ACCEPT | CT27: 000013 | CU27: PEPTIDE NOURISHING LIP SERUM CORAL ROSE | CV27: SKINTIFIC-1232 | CW27: 810114872734 | CX27: 件 | CY27: 件 | CZ27: 1 | DA27: 1 | DD27: 1 | EC27: ZP | EE27: TH01 | EI27: 810114872734 | EJ27: S-1232 | EN27: OTHER
A28: KOO26092200124 | C28: 00000000000000000000 | E28: OTHER | G28: stockout_allocated | H28: 3 | J28: order_allocate | K28: KOL订单 | L28: 2026-09-22 08:01:20 | N28: 00000000000000000000 | O28: KOL | P28: TH01 | Q28: B2C | S28: unnecessary | T28: TH01 | W28: N | X28: N | Y28: intercept_action_nostart | Z28: uncancelled | AE28: CK01967003024260922000671 | AH28: OTHER | AO28: จังหวัดยะลา | AP28: อำเภอกรงปินัง | AQ28: กรงปินัง | AR28: ยะลา/ Yala | AS28: กรงปินัง/ Krong Pinang | AT28: 95000 | AV28: 23 หมู่5 | AW28: อัสมะห์ ยือล๊ะ | AX28: 0937437050 | AZ28: 95000 | BL28: openapi | BV28: Express delivery | CB28: 21 | CC28: 21 | CO28: 805.43 | CS28: ACCEPT | CT28: 000014 | CU28: PEPTIDE NOURISHING LIP SERUM BABY PINK | CV28: SKINTIFIC-1231 | CW28: 810114872727 | CX28: 件 | CY28: 件 | CZ28: 1 | DA28: 1 | DD28: 1 | EC28: ZP | EE28: TH01 | EI28: 810114872727 | EJ28: S-1231 | EN28: OTHER
A29: KOO26092200124 | C29: 00000000000000000000 | E29: OTHER | G29: stockout_allocated | H29: 3 | J29: order_allocate | K29: KOL订单 | L29: 2026-09-22 08:01:20 | N29: 00000000000000000000 | O29: KOL | P29: TH01 | Q29: B2C | S29: unnecessary | T29: TH01 | W29: N | X29: N | Y29: intercept_action_nostart | Z29: uncancelled | AE29: CK01967003024260922000671 | AH29: OTHER | AO29: จังหวัดยะลา | AP29: อำเภอกรงปินัง | AQ29: กรงปินัง | AR29: ยะลา/ Yala | AS29: กรงปินัง/ Krong Pinang | AT29: 95000 | AV29: 23 หมู่5 | AW29: อัสมะห์ ยือล๊ะ | AX29: 0937437050 | AZ29: 95000 | BL29: openapi | BV29: Express delivery | CB29: 21 | CC29: 21 | CO29: 805.43 | CS29: ACCEPT | CT29: 000015 | CU29: BRIGHTENING LIP SERUM CINNAMON ROSE | CV29: SKINTIFIC-1238U | CW29: 4897147693181 | CX29: 件 | CY29: 件 | CZ29: 1 | DA29: 1 | DD29: 1 | EC29: ZP | EE29: TH01 | EN29: OTHER
A30: KOO26092200124 | C30: 00000000000000000000 | E30: OTHER | G30: stockout_allocated | H30: 3 | J30: order_allocate | K30: KOL订单 | L30: 2026-09-22 08:01:20 | N30: 00000000000000000000 | O30: KOL | P30: TH01 | Q30: B2C | S30: unnecessary | T30: TH01 | W30: N | X30: N | Y30: intercept_action_nostart | Z30: uncancelled | AE30: CK01967003024260922000671 | AH30: OTHER | AO30: จังหวัดยะลา | AP30: อำเภอกรงปินัง | AQ30: กรงปินัง | AR30: ยะลา/ Yala | AS30: กรงปินัง/ Krong Pinang | AT30: 95000 | AV30: 23 หมู่5 | AW30: อัสมะห์ ยือล๊ะ | AX30: 0937437050 | AZ30: 95000 | BL30: openapi | BV30: Express delivery | CB30: 21 | CC30: 21 | CO30: 805.43 | CS30: ACCEPT | CT30: 000016 | CU30: 有色唇部精华11U | CV30: SKINTIFIC-12311U | CW30: 4897147693211 | CX30: 件 | CY30: 件 | CZ30: 1 | DA30: 1 | DD30: 1 | EC30: ZP | EE30: TH01 | EN30: OTHER
A31: KOO26092200124 | C31: 00000000000000000000 | E31: OTHER | G31: stockout_allocated | H31: 3 | J31: order_allocate | K31: KOL订单 | L31: 2026-09-22 08:01:20 | N31: 00000000000000000000 | O31: KOL | P31: TH01 | Q31: B2C | S31: unnecessary | T31: TH01 | W31: N | X31: N | Y31: intercept_action_nostart | Z31: uncancelled | AE31: CK01967003024260922000671 | AH31: OTHER | AO31: จังหวัดยะลา | AP31: อำเภอกรงปินัง | AQ31: กรงปินัง | AR31: ยะลา/ Yala | AS31: กรงปินัง/ Krong Pinang | AT31: 95000 | AV31: 23 หมู่5 | AW31: อัสมะห์ ยือล๊ะ | AX31: 0937437050 | AZ31: 95000 | BL31: openapi | BV31: Express delivery | CB31: 21 | CC31: 21 | CO31: 805.43 | CS31: ACCEPT | CT31: 000017 | CU31: PEPTIDE NOURISHING LIP SERUM CHERRY RED | CV31: SKINTIFIC-1233 | CW31: 810114872741 | CX31: 件 | CY31: 件 | CZ31: 1 | DA31: 1 | DD31: 1 | EC31: ZP | EE31: TH01 | EI31: 810114874257 | EJ31: S-1233 | EN31: OTHER
A32: KOO26092200124 | C32: 00000000000000000000 | E32: OTHER | G32: stockout_allocated | H32: 3 | J32: order_allocate | K32: KOL订单 | L32: 2026-09-22 08:01:20 | N32: 00000000000000000000 | O32: KOL | P32: TH01 | Q32: B2C | S32: unnecessary | T32: TH01 | W32: N | X32: N | Y32: intercept_action_nostart | Z32: uncancelled | AE32: CK01967003024260922000671 | AH32: OTHER | AO32: จังหวัดยะลา | AP32: อำเภอกรงปินัง | AQ32: กรงปินัง | AR32: ยะลา/ Yala | AS32: กรงปินัง/ Krong Pinang | AT32: 95000 | AV32: 23 หมู่5 | AW32: อัสมะห์ ยือล๊ะ | AX32: 0937437050 | AZ32: 95000 | BL32: openapi | BV32: Express delivery | CB32: 21 | CC32: 21 | CO32: 805.43 | CS32: ACCEPT | CT32: 000018 | CU32: 有色唇部精华16U | CV32: SKINTIFIC-12316U | CW32: 4897147693655 | CX32: 件 | CY32: 件 | CZ32: 1 | DA32: 1 | DD32: 1 | EC32: ZP | EE32: TH01 | EI32: S--12316U | EN32: OTHER
A33: KOO26092200124 | C33: 00000000000000000000 | E33: OTHER | G33: stockout_allocated | H33: 3 | J33: order_allocate | K33: KOL订单 | L33: 2026-09-22 08:01:20 | N33: 00000000000000000000 | O33: KOL | P33: TH01 | Q33: B2C | S33: unnecessary | T33: TH01 | W33: N | X33: N | Y33: intercept_action_nostart | Z33: uncancelled | AE33: CK01967003024260922000671 | AH33: OTHER | AO33: จังหวัดยะลา | AP33: อำเภอกรงปินัง | AQ33: กรงปินัง | AR33: ยะลา/ Yala | AS33: กรงปินัง/ Krong Pinang | AT33: 95000 | AV33: 23 หมู่5 | AW33: อัสมะห์ ยือล๊ะ | AX33: 0937437050 | AZ33: 95000 | BL33: openapi | BV33: Express delivery | CB33: 21 | CC33: 21 | CO33: 805.43 | CS33: ACCEPT | CT33: 000019 | CU33: BRIGHTENING LIP SERUM FINE WINE | CV33: SKINTIFIC-12313U | CW33: 4897147693624 | CX33: 件 | CY33: 件 | CZ33: 1 | DA33: 1 | DD33: 1 | EC33: ZP | EE33: TH01 | EN33: OTHER
A34: KOO26092200124 | C34: 00000000000000000000 | E34: OTHER | G34: stockout_allocated | H34: 3 | J34: order_allocate | K34: KOL订单 | L34: 2026-09-22 08:01:20 | N34: 00000000000000000000 | O34: KOL | P34: TH01 | Q34: B2C | S34: unnecessary | T34: TH01 | W34: N | X34: N | Y34: intercept_action_nostart | Z34: uncancelled | AE34: CK01967003024260922000671 | AH34: OTHER | AO34: จังหวัดยะลา | AP34: อำเภอกรงปินัง | AQ34: กรงปินัง | AR34: ยะลา/ Yala | AS34: กรงปินัง/ Krong Pinang | AT34: 95000 | AV34: 23 หมู่5 | AW34: อัสมะห์ ยือล๊ะ | AX34: 0937437050 | AZ34: 95000 | BL34: openapi | BV34: Express delivery | CB34: 21 | CC34: 21 | CO34: 805.43 | CS34: ACCEPT | CT34: 000020 | CU34: SKINTIFIC Daily Filter Perfect Skin Tint 01N Natural Vanilla | CV34: SKINTIFIC-17101N | CW34: 810114874684 | CX34: 件 | CY34: 件 | CZ34: 1 | DA34: 1 | DD34: 1 | EC34: ZP | EE34: TH01 | EI34: S-17101N | EN34: OTHER
A35: KOO26092200124 | C35: 00000000000000000000 | E35: OTHER | G35: stockout_allocated | H35: 3 | J35: order_allocate | K35: KOL订单 | L35: 2026-09-22 08:01:20 | N35: 00000000000000000000 | O35: KOL | P35: TH01 | Q35: B2C | S35: unnecessary | T35: TH01 | W35: N | X35: N | Y35: intercept_action_nostart | Z35: uncancelled | AE35: CK01967003024260922000671 | AH35: OTHER | AO35: จังหวัดยะลา | AP35: อำเภอกรงปินัง | AQ35: กรงปินัง | AR35: ยะลา/ Yala | AS35: กรงปินัง/ Krong Pinang | AT35: 95000 | AV35: 23 หมู่5 | AW35: อัสมะห์ ยือล๊ะ | AX35: 0937437050 | AZ35: 95000 | BL35: openapi | BV35: Express delivery | CB35: 21 | CC35: 21 | CO35: 805.43 | CS35: ACCEPT | CT35: 000021 | CU35: SKINTIFIC Daily Filter Perfect Skin Tint 01W Warm vanilla | CV35: SKINTIFIC-17101W | CW35: 810114874691 | CX35: 件 | CY35: 件 | CZ35: 1 | DA35: 1 | DD35: 1 | EC35: ZP | EE35: TH01 | EI35: S-17101W | EN35: OTHER
A36: KOO26092200125 | C36: 00000000000000000000 | E36: OTHER | G36: stockout_allocated | H36: 3 | J36: order_allocate | K36: KOL订单 | L36: 2026-09-22 08:01:21 | N36: 00000000000000000000 | O36: KOL | P36: TH01 | Q36: B2C | S36: unnecessary | T36: TH01 | W36: N | X36: N | Y36: intercept_action_nostart | Z36: uncancelled | AE36: CK01967003024260922000672 | AH36: OTHER | AO36: จังหวัดกรุงเทพมหานคร | AP36: เขตจตุจักร | AQ36: เสนานิคม | AR36: กรุงเทพมหานคร/ Bangkok | AS36: จตุจักร/ Chatuchak | AT36: 10900 | AV36: คอนโดThe key พหลโยธิน34 ห้อง123 ตึกb | AW36: ชนากานต์ | AX36: 0952405705 | AZ36: 10900 | BL36: openapi | BV36: Express delivery | CB36: 2 | CC36: 1 | CO36: 2 | CS36: ACCEPT | CT36: 000001 | CU36: PDRN面霜 | CV36: SKINTIFIC-351 | CW36: 4897147691323 | CX36: 件 | CY36: 件 | CZ36: 2 | DA36: 2 | DD36: 2 | EC36: ZP | EE36: TH01 | EN36: OTHER
A37: KOO26092200126 | C37: 00000000000000000000 | E37: OTHER | G37: stockout_allocated | H37: 3 | J37: order_allocate | K37: KOL订单 | L37: 2026-09-22 08:01:21 | N37: 00000000000000000000 | O37: KOL | P37: TH01 | Q37: B2C | S37: unnecessary | T37: TH01 | W37: N | X37: N | Y37: intercept_action_nostart | Z37: uncancelled | AE37: CK01967003024260922000673 | AH37: OTHER | AO37: กทม | AP37: เขตจตุจักร | AQ37: แขวงเสนานิคม | AR37: กรุงเทพมหานคร/ Bangkok | AS37: จตุจักร/ Chatuchak | AT37: 10900 | AV37: 2034/321 ถนนพหลโยธิน | AW37: ชนาทิป นวัตธนาธร | AX37: 0615166944 | AZ37: 10900 | BL37: openapi | BV37: Express delivery | CB37: 1 | CC37: 1 | CO37: 121 | CS37: ACCEPT | CT37: 000001 | CU37: Retinol Skin Renewal Moisturizer | CV37: SKINTIFIC-183 | CW37: 810114871409 | CX37: 件 | CY37: 件 | CZ37: 1 | DA37: 1 | DD37: 1 | EC37: ZP | EE37: TH01 | EI37: S-183 | EN37: OTHER
A38: KOO26092200127 | C38: 00000000000000000000 | E38: OTHER | G38: stockout_allocated | H38: 3 | J38: order_allocate | K38: KOL订单 | L38: 2026-09-22 08:01:21 | N38: 00000000000000000000 | O38: KOL | P38: TH01 | Q38: B2C | S38: unnecessary | T38: TH01 | W38: N | X38: N | Y38: intercept_action_nostart | Z38: uncancelled | AE38: CK01967003024260922000674 | AH38: OTHER | AO38: จังหวัดกรุงเทพมหานคร | AP38: เขตบางแค | AQ38: หลักสอง | AR38: กรุงเทพมหานคร/ Bangkok | AS38: บางแค/ Bang Khae | AT38: 10160 | AV38: 735 ซ.เพชรเกษม 69 ถ.เพชรเกษม แขวงหลักสอง เขตบางแค กทม. 10160 | AW38: อรชา อินทโต | AX38: 0825466194 | AZ38: 10160 | BL38: openapi | BV38: Express delivery | CB38: 1 | CC38: 1 | CO38: 120 | CS38: ACCEPT | CT38: 000001 | CU38: 5X Ceramide Barrier Moisture Gel- Light Texture | CV38: SKINTIFIC-298 | CW38: 8101148747528 | CX38: 件 | CY38: 件 | CZ38: 1 | DA38: 1 | DD38: 1 | EC38: ZP | EE38: TH01 | EI38: S-298 | EN38: OTHER
A39: KOO26092200128 | C39: 00000000000000000000 | E39: OTHER | G39: stockout_allocated | H39: 3 | J39: order_allocate | K39: KOL订单 | L39: 2026-09-22 08:01:22 | N39: 00000000000000000000 | O39: KOL | P39: TH01 | Q39: B2C | S39: unnecessary | T39: TH01 | W39: N | X39: N | Y39: intercept_action_nostart | Z39: uncancelled | AE39: CK01967003024260922000675 | AH39: OTHER | AO39: จังหวัดกรุงเทพมหานคร | AP39: เขตบางแค | AQ39: หลักสอง | AR39: กรุงเทพมหานคร/ Bangkok | AS39: บางแค/ Bang Khae | AT39: 10160 | AV39: 735 ซ.เพชรเกษม 69 ถ.เพชรเกษม แขวงหลักสอง เขตบางแค กทม. 10160 | AW39: อรชา อินทโต | AX39: 0825466194 | AZ39: 10160 | BL39: openapi | BV39: Express delivery | CB39: 3 | CC39: 1 | CO39: 360 | CS39: ACCEPT | CT39: 000001 | CU39: 5X Ceramide Barrier Moisture Gel- Light Texture | CV39: SKINTIFIC-298 | CW39: 8101148747528 | CX39: 件 | CY39: 件 | CZ39: 3 | DA39: 3 | DD39: 3 | EC39: ZP | EE39: TH01 | EI39: S-298 | EN39: OTHER
A40: KOO26092200129 | C40: 00000000000000000000 | E40: OTHER | G40: stockout_allocated | H40: 3 | J40: order_allocate | K40: KOL订单 | L40: 2026-09-22 08:01:22 | N40: 00000000000000000000 | O40: KOL | P40: TH01 | Q40: B2C | S40: unnecessary | T40: TH01 | W40: N | X40: N | Y40: intercept_action_nostart | Z40: uncancelled | AE40: CK01967003024260922000676 | AH40: OTHER | AO40: ระยอง | AP40: เมืองระยอง | AQ40: เนินพระ | AR40: ระยอง/ Rayong | AS40: เมืองระยอง/ Mueang Rayong | AT40: 21150 | AV40: มินนี่19/25 ถนน กรอกยายชา ต.เนินพระ อ.เมืองระยอง จ.ระยอง 21150 0806027271 | AW40: มินนี่ | AX40: 0806027271 | AZ40: 21150 | BL40: openapi | BV40: Express delivery | CB40: 2 | CC40: 2 | CO40: 262 | CS40: ACCEPT | CT40: 000001 | CU40: Radiance Booster Serum Spray | CV40: SKINTIFIC-170 | CW40: 810114872833 | CX40: 件 | CY40: 件 | CZ40: 1 | DA40: 1 | DD40: 1 | EC40: ZP | EE40: TH01 | EI40: S-170 | EN40: OTHER
...

Sheet ข้อมูลจังหวัด-อำเภอ
A1: จังหวัด | B1: เขต/อำเภอ | C1: จังหวัด | D1: เขต/อำเภอ | Q1: เขต/อำเภอ | R1: Name | S1: จังหวัด | T1: จังหวัด | U1: Name | W1: 级 | X1: Superior Address | Y1: Address Alias Name | Z1: Create/Update Time | AA1: Operation
C2: =ข้อมูลออเดอร์!AR2 -> กรุงเทพมหานคร/ Bangkok | D2: =ข้อมูลออเดอร์!AS2 -> ห้วยขวาง/ Huai Khwang | E2: =SUBSTITUTE(A2,"กทม.","กรุงเทพมหานคร") | F2: =SUBSTITUTE(E2,"กทม","กรุงเทพมหานคร") | G2: =SUBSTITUTE(F2,"กรุงเทพฯ","กรุงเทพ") | H2: =SUBSTITUTE(G2,"bkk","กรุงเทพมหานคร") | I2: =SUBSTITUTE(H2,"Bangkok","กรุงเทพมหานคร") | J2: =SUBSTITUTE(I2,"จ.","") | K2: =SUBSTITUTE(J2,"จังหวัด","") | L2: =IF(K2="กรุงเทพ","กรุงเทพมหานคร",K2) | M2: =SUBSTITUTE(B2,"เขต","") | N2: =SUBSTITUTE(M2,"อ.","") | O2: =SUBSTITUTE(N2,"อำเภอ","") | P2: =IF(O2="เมือง",O2&L2,O2) | Q2: เกาะลันตา | R2: เกาะลันตา/ Ko Lanta | S2: กระบี่ | T2: กระบี่/ Krabi | U2: เกาะลันตา | V2: Ko Lanta | W2: City | X2: กระบี่/ Krabi | Y2: เกาะลันตา / FLASH | Z2: 44090.753 | AA2: Add Address Alias Name
C3: =ข้อมูลออเดอร์!AR3 -> กรุงเทพมหานคร/ Bangkok | D3: =ข้อมูลออเดอร์!AS3 -> ห้วยขวาง/ Huai Khwang | E3: =SUBSTITUTE(A3,"กทม.","กรุงเทพมหานคร") | F3: =SUBSTITUTE(E3,"กทม","กรุงเทพมหานคร") | G3: =SUBSTITUTE(F3,"กรุงเทพฯ","กรุงเทพ") | H3: =SUBSTITUTE(G3,"bkk","กรุงเทพมหานคร") | I3: =SUBSTITUTE(H3,"Bangkok","กรุงเทพมหานคร") | J3: =SUBSTITUTE(I3,"จ.","") | K3: =SUBSTITUTE(J3,"จังหวัด","") | L3: =IF(K3="กรุงเทพ","กรุงเทพมหานคร",K3) | M3: =SUBSTITUTE(B3,"เขต","") | N3: =SUBSTITUTE(M3,"อ.","") | O3: =SUBSTITUTE(N3,"อำเภอ","") | P3: =IF(O3="เมือง",O3&L3,O3) | Q3: เขาพนม | R3: เขาพนม/ Khao Phanom | S3: กาญจนบุรี | T3: กาญจนบุรี/ Kanchanaburi | U3: เขาพนม | V3: Khao Phanom | W3: City | X3: กระบี่/ Krabi | Y3: เขาพนม / FLASH | Z3: 44090.753 | AA3: Add Address Alias Name
C4: =ข้อมูลออเดอร์!AR4 -> ตราด/ Trat | D4: =ข้อมูลออเดอร์!AS4 -> บ่อไร่/ Bo Rai | E4: =SUBSTITUTE(A4,"กทม.","กรุงเทพมหานคร") | F4: =SUBSTITUTE(E4,"กทม","กรุงเทพมหานคร") | G4: =SUBSTITUTE(F4,"กรุงเทพฯ","กรุงเทพ") | H4: =SUBSTITUTE(G4,"bkk","กรุงเทพมหานคร") | I4: =SUBSTITUTE(H4,"Bangkok","กรุงเทพมหานคร") | J4: =SUBSTITUTE(I4,"จ.","") | K4: =SUBSTITUTE(J4,"จังหวัด","") | L4: =IF(K4="กรุงเทพ","กรุงเทพมหานคร",K4) | M4: =SUBSTITUTE(B4,"เขต","") | N4: =SUBSTITUTE(M4,"อ.","") | O4: =SUBSTITUTE(N4,"อำเภอ","") | P4: =IF(O4="เมือง",O4&L4,O4) | Q4: คลองท่อม | R4: คลองท่อม/ Khlong Thom | S4: กาฬสินธุ์ | T4: กาฬสินธุ์/ Kalasin | U4: คลองท่อม | V4: Khlong Thom | W4: City | X4: กระบี่/ Krabi | Y4: คลองท่อม / FLASH | Z4: 44090.753 | AA4: Add Address Alias Name
C5: =ข้อมูลออเดอร์!AR5 -> ตราด/ Trat | D5: =ข้อมูลออเดอร์!AS5 -> บ่อไร่/ Bo Rai | E5: =SUBSTITUTE(A5,"กทม.","กรุงเทพมหานคร") | F5: =SUBSTITUTE(E5,"กทม","กรุงเทพมหานคร") | G5: =SUBSTITUTE(F5,"กรุงเทพฯ","กรุงเทพ") | H5: =SUBSTITUTE(G5,"bkk","กรุงเทพมหานคร") | I5: =SUBSTITUTE(H5,"Bangkok","กรุงเทพมหานคร") | J5: =SUBSTITUTE(I5,"จ.","") | K5: =SUBSTITUTE(J5,"จังหวัด","") | L5: =IF(K5="กรุงเทพ","กรุงเทพมหานคร",K5) | M5: =SUBSTITUTE(B5,"เขต","") | N5: =SUBSTITUTE(M5,"อ.","") | O5: =SUBSTITUTE(N5,"อำเภอ","") | P5: =IF(O5="เมือง",O5&L5,O5) | Q5: ปลายพระยา | R5: ปลายพระยา/ Plai Phraya | S5: กำแพงเพชร | T5: กำแพงเพชร/ Kamphaeng Phet | U5: ปลายพระยา | V5: Plai Phraya | W5: City | X5: กระบี่/ Krabi | Y5: ปลายพระยา / FLASH | Z5: 44090.753 | AA5: Add Address Alias Name
C6: =ข้อมูลออเดอร์!AR6 -> ชลบุรี/ Chonburi | D6: =ข้อมูลออเดอร์!AS6 -> บางละมุง/ Bang Lamung | E6: =SUBSTITUTE(A6,"กทม.","กรุงเทพมหานคร") | F6: =SUBSTITUTE(E6,"กทม","กรุงเทพมหานคร") | G6: =SUBSTITUTE(F6,"กรุงเทพฯ","กรุงเทพ") | H6: =SUBSTITUTE(G6,"bkk","กรุงเทพมหานคร") | I6: =SUBSTITUTE(H6,"Bangkok","กรุงเทพมหานคร") | J6: =SUBSTITUTE(I6,"จ.","") | K6: =SUBSTITUTE(J6,"จังหวัด","") | L6: =IF(K6="กรุงเทพ","กรุงเทพมหานคร",K6) | M6: =SUBSTITUTE(B6,"เขต","") | N6: =SUBSTITUTE(M6,"อ.","") | O6: =SUBSTITUTE(N6,"อำเภอ","") | P6: =IF(O6="เมือง",O6&L6,O6) | Q6: เมืองกระบี่ | R6: เมืองกระบี่/ Mueang Krabi | S6: ขอนแก่น | T6: ขอนแก่น/ Khon Kaen | U6: เมืองกระบี่ | V6: Mueang Krabi | W6: City | X6: กระบี่/ Krabi | Y6: เมืองกระบี่ / FLASH | Z6: 44090.753 | AA6: Add Address Alias Name
C7: =ข้อมูลออเดอร์!AR7 -> ชลบุรี/ Chonburi | D7: =ข้อมูลออเดอร์!AS7 -> บางละมุง/ Bang Lamung | E7: =SUBSTITUTE(A7,"กทม.","กรุงเทพมหานคร") | F7: =SUBSTITUTE(E7,"กทม","กรุงเทพมหานคร") | G7: =SUBSTITUTE(F7,"กรุงเทพฯ","กรุงเทพ") | H7: =SUBSTITUTE(G7,"bkk","กรุงเทพมหานคร") | I7: =SUBSTITUTE(H7,"Bangkok","กรุงเทพมหานคร") | J7: =SUBSTITUTE(I7,"จ.","") | K7: =SUBSTITUTE(J7,"จังหวัด","") | L7: =IF(K7="กรุงเทพ","กรุงเทพมหานคร",K7) | M7: =SUBSTITUTE(B7,"เขต","") | N7: =SUBSTITUTE(M7,"อ.","") | O7: =SUBSTITUTE(N7,"อำเภอ","") | P7: =IF(O7="เมือง",O7&L7,O7) | Q7: ลำทับ | R7: ลำทับ/ Lam Thap | S7: จันทบุรี | T7: จันทบุรี/ Chanthaburi | U7: ลำทับ | V7: Lam Thap | W7: City | X7: กระบี่/ Krabi | Y7: ลำทับ / FLASH | Z7: 45125.566 | AA7: Add Address Alias Name
C8: =ข้อมูลออเดอร์!AR8 -> กรุงเทพมหานคร/ Bangkok | D8: =ข้อมูลออเดอร์!AS8 -> คลองเตย/ Khlong Toei | E8: =SUBSTITUTE(A8,"กทม.","กรุงเทพมหานคร") | F8: =SUBSTITUTE(E8,"กทม","กรุงเทพมหานคร") | G8: =SUBSTITUTE(F8,"กรุงเทพฯ","กรุงเทพ") | H8: =SUBSTITUTE(G8,"bkk","กรุงเทพมหานคร") | I8: =SUBSTITUTE(H8,"Bangkok","กรุงเทพมหานคร") | J8: =SUBSTITUTE(I8,"จ.","") | K8: =SUBSTITUTE(J8,"จังหวัด","") | L8: =IF(K8="กรุงเทพ","กรุงเทพมหานคร",K8) | M8: =SUBSTITUTE(B8,"เขต","") | N8: =SUBSTITUTE(M8,"อ.","") | O8: =SUBSTITUTE(N8,"อำเภอ","") | P8: =IF(O8="เมือง",O8&L8,O8) | Q8: เหนือคลอง | R8: เหนือคลอง/ Nuea Khlong | S8: ฉะเชิงเทรา | T8: ฉะเชิงเทรา/ Chachoengsao | U8: เหนือคลอง | V8: Nuea Khlong | W8: City | X8: กระบี่/ Krabi | Y8: เหนือคลอง / FLASH | Z8: 44090.753 | AA8: Add Address Alias Name
C9: =ข้อมูลออเดอร์!AR9 -> กรุงเทพมหานคร/ Bangkok | D9: =ข้อมูลออเดอร์!AS9 -> คลองเตย/ Khlong Toei | E9: =SUBSTITUTE(A9,"กทม.","กรุงเทพมหานคร") | F9: =SUBSTITUTE(E9,"กทม","กรุงเทพมหานคร") | G9: =SUBSTITUTE(F9,"กรุงเทพฯ","กรุงเทพ") | H9: =SUBSTITUTE(G9,"bkk","กรุงเทพมหานคร") | I9: =SUBSTITUTE(H9,"Bangkok","กรุงเทพมหานคร") | J9: =SUBSTITUTE(I9,"จ.","") | K9: =SUBSTITUTE(J9,"จังหวัด","") | L9: =IF(K9="กรุงเทพ","กรุงเทพมหานคร",K9) | M9: =SUBSTITUTE(B9,"เขต","") | N9: =SUBSTITUTE(M9,"อ.","") | O9: =SUBSTITUTE(N9,"อำเภอ","") | P9: =IF(O9="เมือง",O9&L9,O9) | Q9: อ่าวลึก | R9: อ่าวลึก/ Ao Luek | S9: ชลบุรี | T9: ชลบุรี/ Chonburi | U9: อ่าวลึก | V9: Ao Luek | W9: City | X9: กระบี่/ Krabi | Y9: อ่าวลึก / FLASH | Z9: 44090.753 | AA9: Add Address Alias Name
C10: =ข้อมูลออเดอร์!AR10 -> กรุงเทพมหานคร/ Bangkok | D10: =ข้อมูลออเดอร์!AS10 -> คันนายาว/ Khan Na Yao | E10: =SUBSTITUTE(A10,"กทม.","กรุงเทพมหานคร") | F10: =SUBSTITUTE(E10,"กทม","กรุงเทพมหานคร") | G10: =SUBSTITUTE(F10,"กรุงเทพฯ","กรุงเทพ") | H10: =SUBSTITUTE(G10,"bkk","กรุงเทพมหานคร") | I10: =SUBSTITUTE(H10,"Bangkok","กรุงเทพมหานคร") | J10: =SUBSTITUTE(I10,"จ.","") | K10: =SUBSTITUTE(J10,"จังหวัด","") | L10: =IF(K10="กรุงเทพ","กรุงเทพมหานคร",K10) | M10: =SUBSTITUTE(B10,"เขต","") | N10: =SUBSTITUTE(M10,"อ.","") | O10: =SUBSTITUTE(N10,"อำเภอ","") | P10: =IF(O10="เมือง",O10&L10,O10) | Q10: ด่านมะขามเตี้ย | R10: ด่านมะขามเตี้ย/ Dan Makham Tia District | S10: ชัยนาท | T10: ชัยนาท/ Chainat | U10: ด่านมะขามเตี้ย | V10: Dan Makham Tia District | W10: City | X10: กาญจนบุรี/ Kanchanaburi | Y10: ด่านมะขามเตี้ย / FLASH | Z10: 45125.451 | AA10: Add Address Alias Name
C11: =ข้อมูลออเดอร์!AR11 -> กรุงเทพมหานคร/ Bangkok | D11: =ข้อมูลออเดอร์!AS11 -> คันนายาว/ Khan Na Yao | E11: =SUBSTITUTE(A11,"กทม.","กรุงเทพมหานคร") | F11: =SUBSTITUTE(E11,"กทม","กรุงเทพมหานคร") | G11: =SUBSTITUTE(F11,"กรุงเทพฯ","กรุงเทพ") | H11: =SUBSTITUTE(G11,"bkk","กรุงเทพมหานคร") | I11: =SUBSTITUTE(H11,"Bangkok","กรุงเทพมหานคร") | J11: =SUBSTITUTE(I11,"จ.","") | K11: =SUBSTITUTE(J11,"จังหวัด","") | L11: =IF(K11="กรุงเทพ","กรุงเทพมหานคร",K11) | M11: =SUBSTITUTE(B11,"เขต","") | N11: =SUBSTITUTE(M11,"อ.","") | O11: =SUBSTITUTE(N11,"อำเภอ","") | P11: =IF(O11="เมือง",O11&L11,O11) | Q11: ทองผาภูมิ | R11: ทองผาภูมิ/ Thong Pha Phum | S11: ชัยภูมิ | T11: ชัยภูมิ/ Chaiyaphum | U11: ทองผาภูมิ | V11: Thong Pha Phum | W11: City | X11: กาญจนบุรี/ Kanchanaburi | Y11: ทองผาภูมิ / FLASH | Z11: 44090.753 | AA11: Add Address Alias Name
C12: =ข้อมูลออเดอร์!AR12 -> กรุงเทพมหานคร/ Bangkok | D12: =ข้อมูลออเดอร์!AS12 -> จตุจักร/ Chatuchak | E12: =SUBSTITUTE(A12,"กทม.","กรุงเทพมหานคร") | F12: =SUBSTITUTE(E12,"กทม","กรุงเทพมหานคร") | G12: =SUBSTITUTE(F12,"กรุงเทพฯ","กรุงเทพ") | H12: =SUBSTITUTE(G12,"bkk","กรุงเทพมหานคร") | I12: =SUBSTITUTE(H12,"Bangkok","กรุงเทพมหานคร") | J12: =SUBSTITUTE(I12,"จ.","") | K12: =SUBSTITUTE(J12,"จังหวัด","") | L12: =IF(K12="กรุงเทพ","กรุงเทพมหานคร",K12) | M12: =SUBSTITUTE(B12,"เขต","") | N12: =SUBSTITUTE(M12,"อ.","") | O12: =SUBSTITUTE(N12,"อำเภอ","") | P12: =IF(O12="เมือง",O12&L12,O12) | Q12: ท่าม่วง | R12: ท่าม่วง/ Tha Muang | S12: ชุมพร | T12: ชุมพร/ Chumphon | U12: ท่าม่วง | V12: Tha Muang | W12: City | X12: กาญจนบุรี/ Kanchanaburi | Y12: ท่าม่วง / FLASH | Z12: 45125.451 | AA12: Add Address Alias Name
C13: =ข้อมูลออเดอร์!AR13 -> ปทุมธานี/ Pathum Thani | D13: =ข้อมูลออเดอร์!AS13 -> ธัญบุรี/ Thanyaburi | E13: =SUBSTITUTE(A13,"กทม.","กรุงเทพมหานคร") | F13: =SUBSTITUTE(E13,"กทม","กรุงเทพมหานคร") | G13: =SUBSTITUTE(F13,"กรุงเทพฯ","กรุงเทพ") | H13: =SUBSTITUTE(G13,"bkk","กรุงเทพมหานคร") | I13: =SUBSTITUTE(H13,"Bangkok","กรุงเทพมหานคร") | J13: =SUBSTITUTE(I13,"จ.","") | K13: =SUBSTITUTE(J13,"จังหวัด","") | L13: =IF(K13="กรุงเทพ","กรุงเทพมหานคร",K13) | M13: =SUBSTITUTE(B13,"เขต","") | N13: =SUBSTITUTE(M13,"อ.","") | O13: =SUBSTITUTE(N13,"อำเภอ","") | P13: =IF(O13="เมือง",O13&L13,O13) | Q13: ท่ามะกา | R13: ท่ามะกา/ Tha Maka | S13: เชียงราย | T13: เชียงราย/ Chiang Rai | U13: ท่ามะกา | V13: Tha Maka | W13: City | X13: กาญจนบุรี/ Kanchanaburi | Y13: ท่ามะกา / FLASH | Z13: 44090.753 | AA13: Add Address Alias Name
... C78: =ข้อมูลออเดอร์!AR78 -> กรุงเทพมหานคร/ Bangkok | D78: =ข้อมูลออเดอร์!AS78 -> ห้วยขวาง/ Huai Khwang | E78: =SUBSTITUTE(A78,"กทม.","กรุงเทพมหานคร") | F78: =SUBSTITUTE(E78,"กทม","กรุงเทพมหานคร") | G78: =SUBSTITUTE(F78,"กรุงเทพฯ","กรุงเทพ") | H78: =SUBSTITUTE(G78,"bkk","กรุงเทพมหานคร") | I78: =SUBSTITUTE(H78,"Bangkok","กรุงเทพมหานคร") | J78: =SUBSTITUTE(I78,"จ.","") | K78: =SUBSTITUTE(J78,"จังหวัด","") | L78: =IF(K78="กรุงเทพ","กรุงเทพมหานคร",K78) | M78: =SUBSTITUTE(B78,"เขต","") | N78: =SUBSTITUTE(M78,"อ.","") | O78: =SUBSTITUTE(N78,"อำเภอ","") | P78: =IF(O78="เมือง",O78&L78,O78) | Q78: อุบลรัตน์ | R78: อุบลรัตน์/ Ubolratana | S78: กรุงเทพมหานคร | T78: กรุงเทพมหานคร/ Bangkok | U78: อุบลรัตน์ | V78: Ubolratana | W78: City | X78: ขอนแก่น/ Khon Kaen | Y78: อุบลรัตน์ / FLASH | Z78: 44090.756 | AA78: Add Address Alias Name
C79: =ข้อมูลออเดอร์!AR79 -> กรุงเทพมหานคร/ Bangkok | D79: =ข้อมูลออเดอร์!AS79 -> ห้วยขวาง/ Huai Khwang | E79: =SUBSTITUTE(A79,"กทม.","กรุงเทพมหานคร") | F79: =SUBSTITUTE(E79,"กทม","กรุงเทพมหานคร") | G79: =SUBSTITUTE(F79,"กรุงเทพฯ","กรุงเทพ") | H79: =SUBSTITUTE(G79,"bkk","กรุงเทพมหานคร") | I79: =SUBSTITUTE(H79,"Bangkok","กรุงเทพมหานคร") | J79: =SUBSTITUTE(I79,"จ.","") | K79: =SUBSTITUTE(J79,"จังหวัด","") | L79: =IF(K79="กรุงเทพ","กรุงเทพมหานคร",K79) | M79: =SUBSTITUTE(B79,"เขต","") | N79: =SUBSTITUTE(M79,"อ.","") | O79: =SUBSTITUTE(N79,"อำเภอ","") | P79: =IF(O79="เมือง",O79&L79,O79) | Q79: แก่งหางแมว | R79: แก่งหางแมว/ Kaeng Hang Maeo | U79: แก่งหางแมว | V79: Kaeng Hang Maeo | W79: City | X79: จันทบุรี/ Chanthaburi | Y79: แก่งหางแมว / FLASH | Z79: 44090.757 | AA79: Add Address Alias Name
C80: =ข้อมูลออเดอร์!AR80 -> กรุงเทพมหานคร/ Bangkok | D80: =ข้อมูลออเดอร์!AS80 -> จอมทอง/ Chom Thong | E80: =SUBSTITUTE(A80,"กทม.","กรุงเทพมหานคร") | F80: =SUBSTITUTE(E80,"กทม","กรุงเทพมหานคร") | G80: =SUBSTITUTE(F80,"กรุงเทพฯ","กรุงเทพ") | H80: =SUBSTITUTE(G80,"bkk","กรุงเทพมหานคร") | I80: =SUBSTITUTE(H80,"Bangkok","กรุงเทพมหานคร") | J80: =SUBSTITUTE(I80,"จ.","") | K80: =SUBSTITUTE(J80,"จังหวัด","") | L80: =IF(K80="กรุงเทพ","กรุงเทพมหานคร",K80) | M80: =SUBSTITUTE(B80,"เขต","") | N80: =SUBSTITUTE(M80,"อ.","") | O80: =SUBSTITUTE(N80,"อำเภอ","") | P80: =IF(O80="เมือง",O80&L80,O80) | Q80: ขลุง | R80: ขลุง/ Khlung | U80: ขลุง | V80: Khlung | W80: City | X80: จันทบุรี/ Chanthaburi | Y80: ขลุง / FLASH | Z80: 45125.441 | AA80: Add Address Alias Name
C81: =ข้อมูลออเดอร์!AR81 -> กรุงเทพมหานคร/ Bangkok | D81: =ข้อมูลออเดอร์!AS81 -> จอมทอง/ Chom Thong | E81: =SUBSTITUTE(A81,"กทม.","กรุงเทพมหานคร") | F81: =SUBSTITUTE(E81,"กทม","กรุงเทพมหานคร") | G81: =SUBSTITUTE(F81,"กรุงเทพฯ","กรุงเทพ") | H81: =SUBSTITUTE(G81,"bkk","กรุงเทพมหานคร") | I81: =SUBSTITUTE(H81,"Bangkok","กรุงเทพมหานคร") | J81: =SUBSTITUTE(I81,"จ.","") | K81: =SUBSTITUTE(J81,"จังหวัด","") | L81: =IF(K81="กรุงเทพ","กรุงเทพมหานคร",K81) | M81: =SUBSTITUTE(B81,"เขต","") | N81: =SUBSTITUTE(M81,"อ.","") | O81: =SUBSTITUTE(N81,"อำเภอ","") | P81: =IF(O81="เมือง",O81&L81,O81) | Q81: เขาคิชฌกูฏ | R81: เขาคิชฌกูฏ/ Khao Khitchakut | U81: เขาคิชฌกูฏ | V81: Khao Khitchakut | W81: City | X81: จันทบุรี/ Chanthaburi | Y81: เขาคิชฌกูฏ / FLASH | Z81: 44090.757 | AA81: Add Address Alias Name
C82: =ข้อมูลออเดอร์!AR82 -> กำแพงเพชร/ Kamphaeng Phet | D82: =ข้อมูลออเดอร์!AS82 -> คลองขลุง/ Khlong Khlung | E82: =SUBSTITUTE(A82,"กทม.","กรุงเทพมหานคร") | F82: =SUBSTITUTE(E82,"กทม","กรุงเทพมหานคร") | G82: =SUBSTITUTE(F82,"กรุงเทพฯ","กรุงเทพ") | H82: =SUBSTITUTE(G82,"bkk","กรุงเทพมหานคร") | I82: =SUBSTITUTE(H82,"Bangkok","กรุงเทพมหานคร") | J82: =SUBSTITUTE(I82,"จ.","") | K82: =SUBSTITUTE(J82,"จังหวัด","") | L82: =IF(K82="กรุงเทพ","กรุงเทพมหานคร",K82) | M82: =SUBSTITUTE(B82,"เขต","") | N82: =SUBSTITUTE(M82,"อ.","") | O82: =SUBSTITUTE(N82,"อำเภอ","") | P82: =IF(O82="เมือง",O82&L82,O82) | Q82: ท่าใหม่ | R82: ท่าใหม่/ Tha Mai | U82: ท่าใหม่ | V82: Tha Mai | W82: City | X82: จันทบุรี/ Chanthaburi | Y82: ท่าใหม่ / FLASH | Z82: 45125.44 | AA82: Add Address Alias Name
C83: =ข้อมูลออเดอร์!AR83 -> กำแพงเพชร/ Kamphaeng Phet | D83: =ข้อมูลออเดอร์!AS83 -> คลองขลุง/ Khlong Khlung | E83: =SUBSTITUTE(A83,"กทม.","กรุงเทพมหานคร") | F83: =SUBSTITUTE(E83,"กทม","กรุงเทพมหานคร") | G83: =SUBSTITUTE(F83,"กรุงเทพฯ","กรุงเทพ") | H83: =SUBSTITUTE(G83,"bkk","กรุงเทพมหานคร") | I83: =SUBSTITUTE(H83,"Bangkok","กรุงเทพมหานคร") | J83: =SUBSTITUTE(I83,"จ.","") | K83: =SUBSTITUTE(J83,"จังหวัด","") | L83: =IF(K83="กรุงเทพ","กรุงเทพมหานคร",K83) | M83: =SUBSTITUTE(B83,"เขต","") | N83: =SUBSTITUTE(M83,"อ.","") | O83: =SUBSTITUTE(N83,"อำเภอ","") | P83: =IF(O83="เมือง",O83&L83,O83) | Q83: นายายอาม | R83: นายายอาม/ Na Yai Am | U83: นายายอาม | V83: Na Yai Am | W83: City | X83: จันทบุรี/ Chanthaburi | Y83: นายายอาม / FLASH | Z83: 44090.757 | AA83: Add Address Alias Name
C84: =ข้อมูลออเดอร์!AR84 -> ปทุมธานี/ Pathum Thani | D84: =ข้อมูลออเดอร์!AS84 -> ลำลูกกา/ Lam Luk Ka | E84: =SUBSTITUTE(A84,"กทม.","กรุงเทพมหานคร") | F84: =SUBSTITUTE(E84,"กทม","กรุงเทพมหานคร") | G84: =SUBSTITUTE(F84,"กรุงเทพฯ","กรุงเทพ") | H84: =SUBSTITUTE(G84,"bkk","กรุงเทพมหานคร") | I84: =SUBSTITUTE(H84,"Bangkok","กรุงเทพมหานคร") | J84: =SUBSTITUTE(I84,"จ.","") | K84: =SUBSTITUTE(J84,"จังหวัด","") | L84: =IF(K84="กรุงเทพ","กรุงเทพมหานคร",K84) | M84: =SUBSTITUTE(B84,"เขต","") | N84: =SUBSTITUTE(M84,"อ.","") | O84: =SUBSTITUTE(N84,"อำเภอ","") | P84: =IF(O84="เมือง",O84&L84,O84) | Q84: โป่งน้ำร้อน | R84: โป่งน้ำร้อน/ Pong Nam Ron | U84: โป่งน้ำร้อน | V84: Pong Nam Ron | W84: City | X84: จันทบุรี/ Chanthaburi | Y84: โป่งน้ำร้อน / FLASH | Z84: 44090.757 | AA84: Add Address Alias Name
C85: =ข้อมูลออเดอร์!AR85 -> ปทุมธานี/ Pathum Thani | D85: =ข้อมูลออเดอร์!AS85 -> ลำลูกกา/ Lam Luk Ka | E85: =SUBSTITUTE(A85,"กทม.","กรุงเทพมหานคร") | F85: =SUBSTITUTE(E85,"กทม","กรุงเทพมหานคร") | G85: =SUBSTITUTE(F85,"กรุงเทพฯ","กรุงเทพ") | H85: =SUBSTITUTE(G85,"bkk","กรุงเทพมหานคร") | I85: =SUBSTITUTE(H85,"Bangkok","กรุงเทพมหานคร") | J85: =SUBSTITUTE(I85,"จ.","") | K85: =SUBSTITUTE(J85,"จังหวัด","") | L85: =IF(K85="กรุงเทพ","กรุงเทพมหานคร",K85) | M85: =SUBSTITUTE(B85,"เขต","") | N85: =SUBSTITUTE(M85,"อ.","") | O85: =SUBSTITUTE(N85,"อำเภอ","") | P85: =IF(O85="เมือง",O85&L85,O85) | Q85: มะขาม | R85: มะขาม/ Makham | U85: มะขาม | V85: Makham | W85: City | X85: จันทบุรี/ Chanthaburi | Y85: มะขาม / FLASH | Z85: 44090.757 | AA85: Add Address Alias Name
C86: =ข้อมูลออเดอร์!AR86 -> สมุทรปราการ/ Samut Prakan | D86: =ข้อมูลออเดอร์!AS86 -> บางบ่อ/ Bang Bo | E86: =SUBSTITUTE(A86,"กทม.","กรุงเทพมหานคร") | F86: =SUBSTITUTE(E86,"กทม","กรุงเทพมหานคร") | G86: =SUBSTITUTE(F86,"กรุงเทพฯ","กรุงเทพ") | H86: =SUBSTITUTE(G86,"bkk","กรุงเทพมหานคร") | I86: =SUBSTITUTE(H86,"Bangkok","กรุงเทพมหานคร") | J86: =SUBSTITUTE(I86,"จ.","") | K86: =SUBSTITUTE(J86,"จังหวัด","") | L86: =IF(K86="กรุงเทพ","กรุงเทพมหานคร",K86) | M86: =SUBSTITUTE(B86,"เขต","") | N86: =SUBSTITUTE(M86,"อ.","") | O86: =SUBSTITUTE(N86,"อำเภอ","") | P86: =IF(O86="เมือง",O86&L86,O86) | Q86: เมืองจันทบุรี | R86: เมืองจันทบุรี/ Mueang Chanthaburi | U86: เมืองจันทบุรี | V86: Mueang Chanthaburi | W86: City | X86: จันทบุรี/ Chanthaburi | Y86: เมืองจันทบุรี / FLASH | Z86: 45125.441 | AA86: Add Address Alias Name
C87: =ข้อมูลออเดอร์!AR87 -> สมุทรปราการ/ Samut Prakan | D87: =ข้อมูลออเดอร์!AS87 -> บางบ่อ/ Bang Bo | E87: =SUBSTITUTE(A87,"กทม.","กรุงเทพมหานคร") | F87: =SUBSTITUTE(E87,"กทม","กรุงเทพมหานคร") | G87: =SUBSTITUTE(F87,"กรุงเทพฯ","กรุงเทพ") | H87: =SUBSTITUTE(G87,"bkk","กรุงเทพมหานคร") | I87: =SUBSTITUTE(H87,"Bangkok","กรุงเทพมหานคร") | J87: =SUBSTITUTE(I87,"จ.","") | K87: =SUBSTITUTE(J87,"จังหวัด","") | L87: =IF(K87="กรุงเทพ","กรุงเทพมหานคร",K87) | M87: =SUBSTITUTE(B87,"เขต","") | N87: =SUBSTITUTE(M87,"อ.","") | O87: =SUBSTITUTE(N87,"อำเภอ","") | P87: =IF(O87="เมือง",O87&L87,O87) | Q87: สอยดาว | R87: สอยดาว/ Soi Dao | U87: สอยดาว | V87: Soi Dao | W87: City | X87: จันทบุรี/ Chanthaburi | Y87: สอยดาว / FLASH | Z87: 45125.441 | AA87: Add Address Alias Name
C88: =ข้อมูลออเดอร์!AR88 -> สุราษฎร์ธานี/ Surat Thani | D88: =ข้อมูลออเดอร์!AS88 -> เมืองสุราษฎร์ธานี/ Mueang Surat Thani | E88: =SUBSTITUTE(A88,"กทม.","กรุงเทพมหานคร") | F88: =SUBSTITUTE(E88,"กทม","กรุงเทพมหานคร") | G88: =SUBSTITUTE(F88,"กรุงเทพฯ","กรุงเทพ") | H88: =SUBSTITUTE(G88,"bkk","กรุงเทพมหานคร") | I88: =SUBSTITUTE(H88,"Bangkok","กรุงเทพมหานคร") | J88: =SUBSTITUTE(I88,"จ.","") | K88: =SUBSTITUTE(J88,"จังหวัด","") | L88: =IF(K88="กรุงเทพ","กรุงเทพมหานคร",K88) | M88: =SUBSTITUTE(B88,"เขต","") | N88: =SUBSTITUTE(M88,"อ.","") | O88: =SUBSTITUTE(N88,"อำเภอ","") | P88: =IF(O88="เมือง",O88&L88,O88) | Q88: แหลมสิงห์ | R88: แหลมสิงห์/ Laem Sing | U88: แหลมสิงห์ | V88: Laem Sing | W88: City | X88: จันทบุรี/ Chanthaburi | Y88: แหลมสิงห์ / FLASH | Z88: 45125.441 | AA88: Add Address Alias Name
C89: =ข้อมูลออเดอร์!AR89 -> สุราษฎร์ธานี/ Surat Thani | D89: =ข้อมูลออเดอร์!AS89 -> เมืองสุราษฎร์ธานี/ Mueang Surat Thani | E89: =SUBSTITUTE(A89,"กทม.","กรุงเทพมหานคร") | F89: =SUBSTITUTE(E89,"กทม","กรุงเทพมหานคร") | G89: =SUBSTITUTE(F89,"กรุงเทพฯ","กรุงเทพ") | H89: =SUBSTITUTE(G89,"bkk","กรุงเทพมหานคร") | I89: =SUBSTITUTE(H89,"Bangkok","กรุงเทพมหานคร") | J89: =SUBSTITUTE(I89,"จ.","") | K89: =SUBSTITUTE(J89,"จังหวัด","") | L89: =IF(K89="กรุงเทพ","กรุงเทพมหานคร",K89) | M89: =SUBSTITUTE(B89,"เขต","") | N89: =SUBSTITUTE(M89,"อ.","") | O89: =SUBSTITUTE(N89,"อำเภอ","") | P89: =IF(O89="เมือง",O89&L89,O89) | Q89: คลองเขื่อน | R89: คลองเขื่อน/ Khlong Khuean | U89: คลองเขื่อน | V89: Khlong Khuean | W89: City | X89: ฉะเชิงเทรา/ Chachoengsao | Y89: คลองเขื่อน / FLASH | Z89: 44090.757 | AA89: Add Address Alias Name
C90: =ข้อมูลออเดอร์!AR90 -> ปทุมธานี/ Pathum Thani | D90: =ข้อมูลออเดอร์!AS90 -> คลองหลวง/ Khlong Luang | E90: =SUBSTITUTE(A90,"กทม.","กรุงเทพมหานคร") | F90: =SUBSTITUTE(E90,"กทม","กรุงเทพมหานคร") | G90: =SUBSTITUTE(F90,"กรุงเทพฯ","กรุงเทพ") | H90: =SUBSTITUTE(G90,"bkk","กรุงเทพมหานคร") | I90: =SUBSTITUTE(H90,"Bangkok","กรุงเทพมหานคร") | J90: =SUBSTITUTE(I90,"จ.","") | K90: =SUBSTITUTE(J90,"จังหวัด","") | L90: =IF(K90="กรุงเทพ","กรุงเทพมหานคร",K90) | M90: =SUBSTITUTE(B90,"เขต","") | N90: =SUBSTITUTE(M90,"อ.","") | O90: =SUBSTITUTE(N90,"อำเภอ","") | P90: =IF(O90="เมือง",O90&L90,O90) | Q90: ท่าตะเกียบ | R90: ท่าตะเกียบ/ Tha Takiap | U90: ท่าตะเกียบ | V90: Tha Takiap | W90: City | X90: ฉะเชิงเทรา/ Chachoengsao | Y90: ท่าตะเกียบ / FLASH | Z90: 44090.757 | AA90: Add Address Alias Name
... C200: =ข้อมูลออเดอร์!AR200 -> สุพรรณบุรี/ Suphanburi | D200: =ข้อมูลออเดอร์!AS200 -> สามชุก/ Sam Chuk | E200: =SUBSTITUTE(A200,"กทม.","กรุงเทพมหานคร") | F200: =SUBSTITUTE(E200,"กทม","กรุงเทพมหานคร") | G200: =SUBSTITUTE(F200,"กรุงเทพฯ","กรุงเทพ") | H200: =SUBSTITUTE(G200,"bkk","กรุงเทพมหานคร") | I200: =SUBSTITUTE(H200,"Bangkok","กรุงเทพมหานคร") | J200: =SUBSTITUTE(I200,"จ.","") | K200: =SUBSTITUTE(J200,"จังหวัด","") | L200: =IF(K200="กรุงเทพ","กรุงเทพมหานคร",K200) | M200: =SUBSTITUTE(B200,"เขต","") | N200: =SUBSTITUTE(M200,"อ.","") | O200: =SUBSTITUTE(N200,"อำเภอ","") | P200: =IF(O200="เมือง",O200&L200,O200) | Q200: คลองใหญ่ | R200: คลองใหญ่/ Khlong Yai | U200: คลองใหญ่ | V200: Khlong Yai | W200: City | X200: ตราด/ Trat | Y200: คลองใหญ่ / FLASH | Z200: 44090.763 | AA200: Add Address Alias Name
C201: =ข้อมูลออเดอร์!AR201 -> สุพรรณบุรี/ Suphanburi | D201: =ข้อมูลออเดอร์!AS201 -> สามชุก/ Sam Chuk | E201: =SUBSTITUTE(A201,"กทม.","กรุงเทพมหานคร") | F201: =SUBSTITUTE(E201,"กทม","กรุงเทพมหานคร") | G201: =SUBSTITUTE(F201,"กรุงเทพฯ","กรุงเทพ") | H201: =SUBSTITUTE(G201,"bkk","กรุงเทพมหานคร") | I201: =SUBSTITUTE(H201,"Bangkok","กรุงเทพมหานคร") | J201: =SUBSTITUTE(I201,"จ.","") | K201: =SUBSTITUTE(J201,"จังหวัด","") | L201: =IF(K201="กรุงเทพ","กรุงเทพมหานคร",K201) | M201: =SUBSTITUTE(B201,"เขต","") | N201: =SUBSTITUTE(M201,"อ.","") | O201: =SUBSTITUTE(N201,"อำเภอ","") | P201: =IF(O201="เมือง",O201&L201,O201) | Q201: บ่อไร่ | R201: บ่อไร่/ Bo Rai | U201: บ่อไร่ | V201: Bo Rai | W201: City | X201: ตราด/ Trat | Y201: บ่อไร่ / FLASH | Z201: 44090.763
C202: =ข้อมูลออเดอร์!AR202 -> ศรีสะเกษ/ Sisaket | D202: =ข้อมูลออเดอร์!AS202 -> วังหิน/ Wang Hin | E202: =SUBSTITUTE(A202,"กทม.","กรุงเทพมหานคร") | F202: =SUBSTITUTE(E202,"กทม","กรุงเทพมหานคร") | G202: =SUBSTITUTE(F202,"กรุงเทพฯ","กรุงเทพ") | H202: =SUBSTITUTE(G202,"bkk","กรุงเทพมหานคร") | I202: =SUBSTITUTE(H202,"Bangkok","กรุงเทพมหานคร") | J202: =SUBSTITUTE(I202,"จ.","") | K202: =SUBSTITUTE(J202,"จังหวัด","") | L202: =IF(K202="กรุงเทพ","กรุงเทพมหานคร",K202) | M202: =SUBSTITUTE(B202,"เขต","") | N202: =SUBSTITUTE(M202,"อ.","") | O202: =SUBSTITUTE(N202,"อำเภอ","") | P202: =IF(O202="เมือง",O202&L202,O202) | Q202: เมืองตราด | R202: เมืองตราด/ Mueang Trat | U202: เมืองตราด | V202: Mueang Trat | W202: City | X202: ตราด/ Trat | Y202: เมืองตราด / FLASH | Z202: 45125.484 | AA202: Add Address Alias Name
